Python 3.3.3 (v3.3.3:c3896275c0f6, Nov 18 2013, 21:19:30) [MSC v.1600 64 bit (AMD64)] on win32
Type "copyright", "credits" or "license()" for more information.
>>> ================================ RESTART ================================
>>> 
Traceback (most recent call last):
  File "\\mrgs.school.nz\users\Home\Students\18145\Desktop\Project\TelemetryProject.py", line 26, in <module>
    main_menu(root)
  File "\\mrgs.school.nz\users\Home\Students\18145\Desktop\Project\TelemetryProject.py", line 17, in __init__
    logo = PhotoImage(file="Logo.jpg")
  File "C:\Python33\lib\tkinter\__init__.py", line 3406, in __init__
    Image.__init__(self, 'photo', name, cnf, master, **kw)
  File "C:\Python33\lib\tkinter\__init__.py", line 3362, in __init__
    self.tk.call(('image', 'create', imgtype, name,) + options)
_tkinter.TclError: couldn't recognize data in image file "Logo.jpg"
>>> ================================ RESTART ================================
>>> 
Traceback (most recent call last):
  File "\\mrgs.school.nz\users\Home\Students\18145\Desktop\Project\TelemetryProject.py", line 26, in <module>
    main_menu(root)
  File "\\mrgs.school.nz\users\Home\Students\18145\Desktop\Project\TelemetryProject.py", line 20, in __init__
    root.create_image(image=img)
  File "C:\Python33\lib\tkinter\__init__.py", line 1867, in __getattr__
    return getattr(self.tk, attr)
AttributeError: 'tkapp' object has no attribute 'create_image'
>>> ================================ RESTART ================================
>>> 
Traceback (most recent call last):
  File "\\mrgs.school.nz\users\Home\Students\18145\Desktop\Project\TelemetryProject.py", line 26, in <module>
    main_menu(root)
  File "\\mrgs.school.nz\users\Home\Students\18145\Desktop\Project\TelemetryProject.py", line 20, in __init__
    root.create_image(image=img)
  File "C:\Python33\lib\tkinter\__init__.py", line 1867, in __getattr__
    return getattr(self.tk, attr)
AttributeError: 'tkapp' object has no attribute 'create_image'
>>> ================================ RESTART ================================
>>> 
Traceback (most recent call last):
  File "\\mrgs.school.nz\users\Home\Students\18145\Desktop\Project\TelemetryProject.py", line 26, in <module>
    main_menu(root)
  File "\\mrgs.school.nz\users\Home\Students\18145\Desktop\Project\TelemetryProject.py", line 20, in __init__
    root.create_image(950,300, image=img)
  File "C:\Python33\lib\tkinter\__init__.py", line 1867, in __getattr__
    return getattr(self.tk, attr)
AttributeError: 'tkapp' object has no attribute 'create_image'
>>> ================================ RESTART ================================
>>> 
Traceback (most recent call last):
  File "\\mrgs.school.nz\users\Home\Students\18145\Desktop\Project\TelemetryProject.py", line 28, in <module>
    main_menu(root)
TypeError: 'Tk' object is not callable
>>> ================================ RESTART ================================
>>> 
Traceback (most recent call last):
  File "\\mrgs.school.nz\users\Home\Students\18145\Desktop\Project\TelemetryProject.py", line 28, in <module>
    main_menu(root)
  File "\\mrgs.school.nz\users\Home\Students\18145\Desktop\Project\TelemetryProject.py", line 20, in __init__
    root.create_image(950,300, image=img)
  File "C:\Python33\lib\tkinter\__init__.py", line 1867, in __getattr__
    return getattr(self.tk, attr)
AttributeError: 'tkapp' object has no attribute 'create_image'
>>> ================================ RESTART ================================
>>> 
Traceback (most recent call last):
  File "\\mrgs.school.nz\users\Home\Students\18145\Desktop\Project\TelemetryProject.py", line 28, in <module>
    main_menu(root)
  File "\\mrgs.school.nz\users\Home\Students\18145\Desktop\Project\TelemetryProject.py", line 20, in __init__
    first_window.create_image(950,300, image=img)
  File "C:\Python33\lib\tkinter\__init__.py", line 1867, in __getattr__
    return getattr(self.tk, attr)
AttributeError: 'tkapp' object has no attribute 'create_image'
>>> 
